Workbook

Sheet 单机性能指标
A1: xrouter 单机性能测试指标表（2026-10-14整理）
A2: 沿用模板指标布局；输入100 token，mock首token等待500ms，batch=1，30s爬坡；20/50/100 tok/s为单流配置速度。
A3: 36档均有效、零记录错误；A/B/C/E=r10，D/F=r11。时延是16分片范围，不是整体分位数。旧对照及集群数据不带入。
A4: 每个流的输出阶段时长 | B4: 稳态测试时长 | C4: 设定单流tok/s | D4: VUS | E4: TTFT超过mock固定等待（ms） | H4: 请求成功率 | I4: 整轮平均RPS | J4: 流时长减模板理论值（ms） | M4: 网络接收批间隔差（ms） | P4: 整轮输出TPS（tok/s） | Q4: 稳态成功RPS | R4: 稳态输出TPS（tok/s）
E5: P50分片范围 | F5: P90分片范围 | G5: P99分片范围 | J5: P50分片范围 | K5: P90分片范围 | L5: P99分片范围 | M5: P50 | N5: P90 | O5: P99
A6: 5s | B6: 300s | C6: 20 | D6: 1000 | E6: =TEXT('单机全档'!T2,"0.000")&"–"&TEXT('单机全档'!U2,"0.000") -> 4.443–4.790 | F6: =TEXT('单机全档'!V2,"0.000")&"–"&TEXT('单机全档'!W2,"0.000") -> 11.228–12.417 | G6: =TEXT('单机全档'!X2,"0.000")&"–"&TEXT('单机全档'!Y2,"0.000") -> 20.392–22.275 | H6: ='单机全档'!M2 -> 1 | I6: ='单机全档'!N2 -> 173.63295 | J6: =TEXT('单机全档'!Z2,"0.000")&"–"&TEXT('单机全档'!AA2,"0.000") -> -45.667–-45.412 | K6: =TEXT('单机全档'!AB2,"0.000")&"–"&TEXT('单机全档'!AC2,"0.000") -> -40.438–-39.832 | L6: =TEXT('单机全档'!AD2,"0.000")&"–"&TEXT('单机全档'!AE2,"0.000") -> -32.527–-30.786 | M6: 未测 | N6: 未测 | O6: 未测 | P6: =I6*'单机全档'!E2 -> 17363.295 | Q6: ='单机全档'!O2 -> 183.24 | R6: =Q6*'单机全档'!E2 -> 18324
D7: 2000 | E7: =TEXT('单机全档'!T3,"0.000")&"–"&TEXT('单机全档'!U3,"0.000") -> 3.449–3.535 | F7: =TEXT('单机全档'!V3,"0.000")&"–"&TEXT('单机全档'!W3,"0.000") -> 6.315–6.487 | G7: =TEXT('单机全档'!X3,"0.000")&"–"&TEXT('单机全档'!Y3,"0.000") -> 9.544–10.324 | H7: ='单机全档'!M3 -> 1 | I7: ='单机全档'!N3 -> 347.28297 | J7: =TEXT('单机全档'!Z3,"0.000")&"–"&TEXT('单机全档'!AA3,"0.000") -> -46.242–-46.164 | K7: =TEXT('单机全档'!AB3,"0.000")&"–"&TEXT('单机全档'!AC3,"0.000") -> -43.496–-43.281 | L7: =TEXT('单机全档'!AD3,"0.000")&"–"&TEXT('单机全档'!AE3,"0.000") -> -40.675–-39.989 | M7: 未测 | N7: 未测 | O7: 未测 | P7: =I7*'单机全档'!E3 -> 34728.297 | Q7: ='单机全档'!O3 -> 366.46667 | R7: =Q7*'单机全档'!E3 -> 36646.667
D8: 5000 | E8: =TEXT('单机全档'!T4,"0.000")&"–"&TEXT('单机全档'!U4,"0.000") -> 2.534–2.574 | F8: =TEXT('单机全档'!V4,"0.000")&"–"&TEXT('单机全档'!W4,"0.000") -> 3.739–3.804 | G8: =TEXT('单机全档'!X4,"0.000")&"–"&TEXT('单机全档'!Y4,"0.000") -> 5.244–5.553 | H8: ='单机全档'!M4 -> 1 | I8: ='单机全档'!N4 -> 868.30822 | J8: =TEXT('单机全档'!Z4,"0.000")&"–"&TEXT('单机全档'!AA4,"0.000") -> -46.752–-46.712 | K8: =TEXT('单机全档'!AB4,"0.000")&"–"&TEXT('单机全档'!AC4,"0.000") -> -45.379–-45.292 | L8: =TEXT('单机全档'!AD4,"0.000")&"–"&TEXT('单机全档'!AE4,"0.000") -> -43.811–-43.576 | M8: 未测 | N8: 未测 | O8: 未测 | P8: =I8*'单机全档'!E4 -> 86830.822 | Q8: ='单机全档'!O4 -> 916.36333 | R8: =Q8*'单机全档'!E4 -> 91636.333
D9: 10000 | E9: =TEXT('单机全档'!T5,"0.000")&"–"&TEXT('单机全档'!U5,"0.000") -> 2.390–2.411 | F9: =TEXT('单机全档'!V5,"0.000")&"–"&TEXT('单机全档'!W5,"0.000") -> 3.546–3.594 | G9: =TEXT('单机全档'!X5,"0.000")&"–"&TEXT('单机全档'!Y5,"0.000") -> 5.270–5.633 | H9: ='单机全档'!M5 -> 1 | I9: ='单机全档'!N5 -> 1736.442 | J9: =TEXT('单机全档'!Z5,"0.000")&"–"&TEXT('单机全档'!AA5,"0.000") -> -46.703–-46.666 | K9: =TEXT('单机全档'!AB5,"0.000")&"–"&TEXT('单机全档'!AC5,"0.000") -> -45.351–-45.305 | L9: =TEXT('单机全档'!AD5,"0.000")&"–"&TEXT('单机全档'!AE5,"0.000") -> -43.640–-43.465 | M9: 未测 | N9: 未测 | O9: 未测 | P9: =I9*'单机全档'!E5 -> 173644.2 | Q9: ='单机全档'!O5 -> 1832.64 | R9: =Q9*'单机全档'!E5 -> 183264
D10: 15000 | E10: =TEXT('单机全档'!T6,"0.000")&"–"&TEXT('单机全档'!U6,"0.000") -> 2.370–2.402 | F10: =TEXT('单机全档'!V6,"0.000")&"–"&TEXT('单机全档'!W6,"0.000") -> 3.588–3.643 | G10: =TEXT('单机全档'!X6,"0.000")&"–"&TEXT('单机全档'!Y6,"0.000") -> 6.086–6.427 | H10: ='单机全档'!M6 -> 1 | I10: ='单机全档'!N6 -> 2604.4613 | J10: =TEXT('单机全档'!Z6,"0.000")&"–"&TEXT('单机全档'!AA6,"0.000") -> -46.620–-46.585 | K10: =TEXT('单机全档'!AB6,"0.000")&"–"&TEXT('单机全档'!AC6,"0.000") -> -45.230–-45.174 | L10: =TEXT('单机全档'!AD6,"0.000")&"–"&TEXT('单机全档'!AE6,"0.000") -> -42.941–-42.539 | M10: 未测 | N10: 未测 | O10: 未测 | P10: =I10*'单机全档'!E6 -> 260446.13 | Q10: ='单机全档'!O6 -> 2748.8033 | R10: =Q10*'单机全档'!E6 -> 274880.33
D11: 18000 | E11: =TEXT('单机全档'!T7,"0.000")&"–"&TEXT('单机全档'!U7,"0.000") -> 2.367–2.394 | F11: =TEXT('单机全档'!V7,"0.000")&"–"&TEXT('单机全档'!W7,"0.000") -> 3.532–3.574 | G11: =TEXT('单机全档'!X7,"0.000")&"–"&TEXT('单机全档'!Y7,"0.000") -> 8.348–9.521 | H11: ='单机全档'!M7 -> 1 | I11: ='单机全档'!N7 -> 3125.2536 | J11: =TEXT('单机全档'!Z7,"0.000")&"–"&TEXT('单机全档'!AA7,"0.000") -> -46.576–-46.544 | K11: =TEXT('单机全档'!AB7,"0.000")&"–"&TEXT('单机全档'!AC7,"0.000") -> -45.233–-45.168 | L11: =TEXT('单机全档'!AD7,"0.000")&"–"&TEXT('单机全档'!AE7,"0.000") -> -41.160–-40.048 | M11: 未测 | N11: 未测 | O11: 未测 | P11: =I11*'单机全档'!E7 -> 312525.36 | Q11: ='单机全档'!O7 -> 3298.3967 | R11: =Q11*'单机全档'!E7 -> 329839.67
C12: 50 | D12: 1000 | E12: =TEXT('单机全档'!T8,"0.000")&"–"&TEXT('单机全档'!U8,"0.000") -> 3.250–3.357 | F12: =TEXT('单机全档'!V8,"0.000")&"–"&TEXT('单机全档'!W8,"0.000") -> 5.568–5.839 | G12: =TEXT('单机全档'!X8,"0.000")&"–"&TEXT('单机全档'!Y8,"0.000") -> 8.167–9.075 | H12: ='单机全档'!M8 -> 1 | I12: ='单机全档'!N8 -> 172.55178 | J12: =TEXT('单机全档'!Z8,"0.000")&"–"&TEXT('单机全档'!AA8,"0.000") -> -16.369–-16.195 | K12: =TEXT('单机全档'!AB8,"0.000")&"–"&TEXT('单机全档'!AC8,"0.000") -> -14.069–-13.818 | L12: =TEXT('单机全档'!AD8,"0.000")&"–"&TEXT('单机全档'!AE8,"0.000") -> -11.514–-10.792 | M12: 未测 | N12: 未测 | O12: 未测 | P12: =I12*'单机全档'!E8 -> 43137.946 | Q12: ='单机全档'!O8 -> 182.09 | R12: =Q12*'单机全档'!E8 -> 45522.5
D13: 2000 | E13: =TEXT('单机全档'!T9,"0.000")&"–"&TEXT('单机全档'!U9,"0.000") -> 2.631–2.667 | F13: =TEXT('单机全档'!V9,"0.000")&"–"&TEXT('单机全档'!W9,"0.000") -> 3.825–3.915 | G13: =TEXT('单机全档'!X9,"0.000")&"–"&TEXT('单机全档'!Y9,"0.000") -> 5.309–5.638 | H13: ='单机全档'!M9 -> 1 | I13: ='单机全档'!N9 -> 345.10598 | J13: =TEXT('单机全档'!Z9,"0.000")&"–"&TEXT('单机全档'!AA9,"0.000") -> -16.696–-16.654 | K13: =TEXT('单机全档'!AB9,"0.000")&"–"&TEXT('单机全档'!AC9,"0.000") -> -15.304–-15.210 | L13: =TEXT('单机全档'!AD9,"0.000")&"–"&TEXT('单机全档'!AE9,"0.000") -> -13.817–-13.554 | M13: 未测 | N13: 未测 | O13: 未测 | P13: =I13*'单机全档'!E9 -> 86276.496 | Q13: ='单机全档'!O9 -> 364.18667 | R13: =Q13*'单机全档'!E9 -> 91046.667
D14: 5000 | E14: =TEXT('单机全档'!T10,"0.000")&"–"&TEXT('单机全档'!U10,"0.000") -> 1.843–1.874 | F14: =TEXT('单机全档'!V10,"0.000")&"–"&TEXT('单机全档'!W10,"0.000") -> 2.717–2.771 | G14: =TEXT('单机全档'!X10,"0.000")&"–"&TEXT('单机全档'!Y10,"0.000") -> 3.675–3.799 | H14: ='单机全档'!M10 -> 1 | I14: ='单机全档'!N10 -> 862.67964 | J14: =TEXT('单机全档'!Z10,"0.000")&"–"&TEXT('单机全档'!AA10,"0.000") -> -16.954–-16.914 | K14: =TEXT('单机全档'!AB10,"0.000")&"–"&TEXT('单机全档'!AC10,"0.000") -> -16.037–-15.974 | L14: =TEXT('单机全档'!AD10,"0.000")&"–"&TEXT('单机全档'!AE10,"0.000") -> -14.866–-14.612 | M14: 未测 | N14: 未测 | O14: 未测 | P14: =I14*'单机全档'!E10 -> 215669.91 | Q14: ='单机全档'!O10 -> 910.45333 | R14: =Q14*'单机全档'!E10 -> 227613.33
D15: 10000 | E15: =TEXT('单机全档'!T11,"0.000")&"–"&TEXT('单机全档'!U11,"0.000") -> 2.011–2.040 | F15: =TEXT('单机全档'!V11,"0.000")&"–"&TEXT('单机全档'!W11,"0.000") -> 2.918–2.977 | G15: =TEXT('单机全档'!X11,"0.000")&"–"&TEXT('单机全档'!Y11,"0.000") -> 4.805–5.669 | H15: ='单机全档'!M11 -> 1 | I15: ='单机全档'!N11 -> 1725.0116 | J15: =TEXT('单机全档'!Z11,"0.000")&"–"&TEXT('单机全档'!AA11,"0.000") -> -16.728–-16.688 | K15: =TEXT('单机全档'!AB11,"0.000")&"–"&TEXT('单机全档'!AC11,"0.000") -> -15.704–-15.646 | L15: =TEXT('单机全档'!AD11,"0.000")&"–"&TEXT('单机全档'!AE11,"0.000") -> -13.480–-12.581 | M15: 未测 | N15: 未测 | O15: 未测 | P15: =I15*'单机全档'!E11 -> 431252.9 | Q15: ='单机全档'!O11 -> 1820.6033 | R15: =Q15*'单机全档'!E11 -> 455150.83
D16: 15000 | E16: =TEXT('单机全档'!T12,"0.000")&"–"&TEXT('单机全档'!U12,"0.000") -> 2.084–2.109 | F16: =TEXT('单机全档'!V12,"0.000")&"–"&TEXT('单机全档'!W12,"0.000") -> 3.253–3.345 | G16: =TEXT('单机全档'!X12,"0.000")&"–"&TEXT('单机全档'!Y12,"0.000") -> 10.256–12.187 | H16: ='单机全档'!M12 -> 1 | I16: ='单机全档'!N12 -> 2587.4809 | J16: =TEXT('单机全档'!Z12,"0.000")&"–"&TEXT('单机全档'!AA12,"0.000") -> -16.591–-16.554 | K16: =TEXT('单机全档'!AB12,"0.000")&"–"&TEXT('单机全档'!AC12,"0.000") -> -15.208–-15.089 | L16: =TEXT('单机全档'!AD12,"0.000")&"–"&TEXT('单机全档'!AE12,"0.000") -> -8.411–-6.576 | M16: 未测 | N16: 未测 | O16: 未测 | P16: =I16*'单机全档'!E12 -> 646870.21 | Q16: ='单机全档'!O12 -> 2731.08 | R16: =Q16*'单机全档'!E12 -> 682770
D17: 18000 | E17: =TEXT('单机全档'!T13,"0.000")&"–"&TEXT('单机全档'!U13,"0.000") -> 2.123–2.154 | F17: =TEXT('单机全档'!V13,"0.000")&"–"&TEXT('单机全档'!W13,"0.000") -> 3.930–4.197 | G17: =TEXT('单机全档'!X13,"0.000")&"–"&TEXT('单机全档'!Y13,"0.000") -> 15.729–19.314 | H17: ='单机全档'!M13 -> 1 | I17: ='单机全档'!N13 -> 3105.1143 | J17: =TEXT('单机全档'!Z13,"0.000")&"–"&TEXT('单机全档'!AA13,"0.000") -> -16.495–-16.460 | K17: =TEXT('单机全档'!AB13,"0.000")&"–"&TEXT('单机全档'!AC13,"0.000") -> -14.195–-13.849 | L17: =TEXT('单机全档'!AD13,"0.000")&"–"&TEXT('单机全档'!AE13,"0.000") -> -2.405–-0.632 | M17: 未测 | N17: 未测 | O17: 未测 | P17: =I17*'单机全档'!E13 -> 776278.57 | Q17: ='单机全档'!O13 -> 3277.36 | R17: =Q17*'单机全档'!E13 -> 819340
C18: 100 | D18: 1000 | E18: =TEXT('单机全档'!T14,"0.000")&"–"&TEXT('单机全档'!U14,"0.000") -> 2.678–2.736 | F18: =TEXT('单机全档'!V14,"0.000")&"–"&TEXT('单机全档'!W14,"0.000") -> 3.887–3.984 | G18: =TEXT('单机全档'!X14,"0.000")&"–"&TEXT('单机全档'!Y14,"0.000") -> 5.252–5.606 | H18: ='单机全档'!M14 -> 1 | I18: ='单机全档'!N14 -> 172.08432 | J18: =TEXT('单机全档'!Z14,"0.000")&"–"&TEXT('单机全档'!AA14,"0.000") -> -6.653–-6.545 | K18: =TEXT('单机全档'!AB14,"0.000")&"–"&TEXT('单机全档'!AC14,"0.000") -> -5.234–-5.102 | L18: =TEXT('单机全档'!AD14,"0.000")&"–"&TEXT('单机全档'!AE14,"0.000") -> -3.760–-3.397 | M18: 未测 | N18: 未测 | O18: 未测 | P18: =I18*'单机全档'!E14 -> 86042.161 | Q18: ='单机全档'!O14 -> 181.55667 | R18: =Q18*'单机全档'!E14 -> 90778.333
D19: 2000 | E19: =TEXT('单机全档'!T15,"0.000")&"–"&TEXT('单机全档'!U15,"0.000") -> 2.001–2.044 | F19: =TEXT('单机全档'!V15,"0.000")&"–"&TEXT('单机全档'!W15,"0.000") -> 3.000–3.062 | G19: =TEXT('单机全档'!X15,"0.000")&"–"&TEXT('单机全档'!Y15,"0.000") -> 3.870–4.106 | H19: ='单机全档'!M15 -> 1 | I19: ='单机全档'!N15 -> 344.14033 | J19: =TEXT('单机全档'!Z15,"0.000")&"–"&TEXT('单机全档'!AA15,"0.000") -> -6.888–-6.840 | K19: =TEXT('单机全档'!AB15,"0.000")&"–"&TEXT('单机全档'!AC15,"0.000") -> -5.836–-5.796 | L19: =TEXT('单机全档'!AD15,"0.000")&"–"&TEXT('单机全档'!AE15,"0.000") -> -4.739–-4.459 | M19: 未测 | N19: 未测 | O19: 未测 | P19: =I19*'单机全档'!E15 -> 172070.16 | Q19: ='单机全档'!O15 -> 363.15333 | R19: =Q19*'单机全档'!E15 -> 181576.67
D20: 5000 | E20: =TEXT('单机全档'!T16,"0.000")&"–"&TEXT('单机全档'!U16,"0.000") -> 1.949–1.989 | F20: =TEXT('单机全档'!V16,"0.000")&"–"&TEXT('单机全档'!W16,"0.000") -> 2.665–2.702 | G20: =TEXT('单机全档'!X16,"0.000")&"–"&TEXT('单机全档'!Y16,"0.000") -> 4.154–4.616 | H20: ='单机全档'!M16 -> 1 | I20: ='单机全档'!N16 -> 860.165 | J20: =TEXT('单机全档'!Z16,"0.000")&"–"&TEXT('单机全档'!AA16,"0.000") -> -6.677–-6.602 | K20: =TEXT('单机全档'!AB16,"0.000")&"–"&TEXT('单机全档'!AC16,"0.000") -> -5.732–-5.646 | L20: =TEXT('单机全档'!AD16,"0.000")&"–"&TEXT('单机全档'!AE16,"0.000") -> -4.042–-3.488 | M20: 未测 | N20: 未测 | O20: 未测 | P20: =I20*'单机全档'!E16 -> 430082.5 | Q20: ='单机全档'!O16 -> 907.76333 | R20: =Q20*'单机全档'!E16 -> 453881.67
D21: 10000 | E21: =TEXT('单机全档'!T17,"0.000")&"–"&TEXT('单机全档'!U17,"0.000") -> 2.023–2.058 | F21: =TEXT('单机全档'!V17,"0.000")&"–"&TEXT('单机全档'!W17,"0.000") -> 3.270–3.527 | G21: =TEXT('单机全档'!X17,"0.000")&"–"&TEXT('单机全档'!Y17,"0.000") -> 13.055–15.840 | H21: ='单机全档'!M17 -> 1 | I21: ='单机全档'!N17 -> 1720.5995 | J21: =TEXT('单机全档'!Z17,"0.000")&"–"&TEXT('单机全档'!AA17,"0.000") -> -6.578–-6.515 | K21: =TEXT('单机全档'!AB17,"0.000")&"–"&TEXT('单机全档'!AC17,"0.000") -> -4.831–-4.435 | L21: =TEXT('单机全档'!AD17,"0.000")&"–"&TEXT('单机全档'!AE17,"0.000") -> 3.886–6.976 | M21: 未测 | N21: 未测 | O21: 未测 | P21: =I21*'单机全档'!E17 -> 860299.76 | Q21: ='单机全档'!O17 -> 1815.99 | R21: =Q21*'单机全档'!E17 -> 907995
D22: 15000 | E22: =TEXT('单机全档'!T18,"0.000")&"–"&TEXT('单机全档'!U18,"0.000") -> 18.330–18.515 | F22: =TEXT('单机全档'!V18,"0.000")&"–"&TEXT('单机全档'!W18,"0.000") -> 35.758–36.409 | G22: =TEXT('单机全档'!X18,"0.000")&"–"&TEXT('单机全档'!Y18,"0.000") -> 69.263–89.599 | H22: ='单机全档'!M18 -> 1 | I22: ='单机全档'!N18 -> 2566.0875 | J22: =TEXT('单机全档'!Z18,"0.000")&"–"&TEXT('单机全档'!AA18,"0.000") -> 17.531–17.972 | K22: =TEXT('单机全档'!AB18,"0.000")&"–"&TEXT('单机全档'!AC18,"0.000") -> 56.439–60.175 | L22: =TEXT('单机全档'!AD18,"0.000")&"–"&TEXT('单机全档'!AE18,"0.000") -> 192.750–208.930 | M22: 未测 | N22: 未测 | O22: 未测 | P22: =I22*'单机全档'!E18 -> 1283043.8 | Q22: ='单机全档'!O18 -> 2707.8967 | R22: =Q22*'单机全档'!E18 -> 1353948.3
D23: 18000 | E23: =TEXT('单机全档'!T19,"0.000")&"–"&TEXT('单机全档'!U19,"0.000") -> 22.076–22.411 | F23: =TEXT('单机全档'!V19,"0.000")&"–"&TEXT('单机全档'!W19,"0.000") -> 42.316–44.327 | G23: =TEXT('单机全档'!X19,"0.000")&"–"&TEXT('单机全档'!Y19,"0.000") -> 107.343–182.922 | H23: ='单机全档'!M19 -> 1 | I23: ='单机全档'!N19 -> 3053.3123 | J23: =TEXT('单机全档'!Z19,"0.000")&"–"&TEXT('单机全档'!AA19,"0.000") -> 26.913–27.986 | K23: =TEXT('单机全档'!AB19,"0.000")&"–"&TEXT('单机全档'!AC19,"0.000") -> 181.411–190.672 | L23: =TEXT('单机全档'!AD19,"0.000")&"–"&TEXT('单机全档'!AE19,"0.000") -> 630.939–659.505 | M23: 未测 | N23: 未测 | O23: 未测 | P23: =I23*'单机全档'!E19 -> 1526656.1 | Q23: ='单机全档'!O19 -> 3220.95 | R23: =Q23*'单机全档'!E19 -> 1610475
A24: 60s | B24: 640s | C24: 20 | D24: 1000 | E24: =TEXT('单机全档'!T20,"0.000")&"–"&TEXT('单机全档'!U20,"0.000") -> 4.871–5.408 | F24: =TEXT('单机全档'!V20,"0.000")&"–"&TEXT('单机全档'!W20,"0.000") -> 10.181–11.302 | G24: =TEXT('单机全档'!X20,"0.000")&"–"&TEXT('单机全档'!Y20,"0.000") -> 15.231–20.934 | H24: ='单机全档'!M20 -> 1 | I24: ='单机全档'!N20 -> 15.288064 | J24: =TEXT('单机全档'!Z20,"0.000")&"–"&TEXT('单机全档'!AA20,"0.000") -> -45.310–-44.950 | K24: =TEXT('单机全档'!AB20,"0.000")&"–"&TEXT('单机全档'!AC20,"0.000") -> -40.513–-39.710 | L24: =TEXT('单机全档'!AD20,"0.000")&"–"&TEXT('单机全档'!AE20,"0.000") -> -35.278–-32.482 | M24: 未测 | N24: 未测 | O24: 未测 | P24: =I24*'单机全档'!E20 -> 18345.677 | Q24: ='单机全档'!O20 -> 15.88125 | R24: =Q24*'单机全档'!E20 -> 19057.5
D25: 2000 | E25: =TEXT('单机全档'!T21,"0.000")&"–"&TEXT('单机全档'!U21,"0.000") -> 3.560–3.748 | F25: =TEXT('单机全档'!V21,"0.000")&"–"&TEXT('单机全档'!W21,"0.000") -> 6.248–6.640 | G25: =TEXT('单机全档'!X21,"0.000")&"–"&TEXT('单机全档'!Y21,"0.000") -> 10.662–15.099 | H25: ='单机全档'!M21 -> 1 | I25: ='单机全档'!N21 -> 30.568864 | J25: =TEXT('单机全档'!Z21,"0.000")&"–"&TEXT('单机全档'!AA21,"0.000") -> -45.992–-45.799 | K25: =TEXT('单机全档'!AB21,"0.000")&"–"&TEXT('单机全档'!AC21,"0.000") -> -43.270–-42.869 | L25: =TEXT('单机全档'!AD21,"0.000")&"–"&TEXT('单机全档'!AE21,"0.000") -> -40.441–-37.411 | M25: 未测 | N25: 未测 | O25: 未测 | P25: =I25*'单机全档'!E21 -> 36682.637 | Q25: ='单机全档'!O21 -> 31.759375 | R25: =Q25*'单机全档'!E21 -> 38111.25
D26: 5000 | E26: =TEXT('单机全档'!T22,"0.000")&"–"&TEXT('单机全档'!U22,"0.000") -> 2.659–2.728 | F26: =TEXT('单机全档'!V22,"0.000")&"–"&TEXT('单机全档'!W22,"0.000") -> 3.864–3.993 | G26: =TEXT('单机全档'!X22,"0.000")&"–"&TEXT('单机全档'!Y22,"0.000") -> 6.725–8.478 | H26: ='单机全档'!M22 -> 1 | I26: ='单机全档'!N22 -> 76.402357 | J26: =TEXT('单机全档'!Z22,"0.000")&"–"&TEXT('单机全档'!AA22,"0.000") -> -46.426–-46.287 | K26: =TEXT('单机全档'!AB22,"0.000")&"–"&TEXT('单机全档'!AC22,"0.000") -> -45.015–-44.816 | L26: =TEXT('单机全档'!AD22,"0.000")&"–"&TEXT('单机全档'!AE22,"0.000") -> -42.780–-41.262 | M26: 未测 | N26: 未测 | O26: 未测 | P26: =I26*'单机全档'!E22 -> 91682.828 | Q26: ='单机全档'!O22 -> 79.382812 | R26: =Q26*'单机全档'!E22 -> 95259.375
D27: 10000 | E27: =TEXT('单机全档'!T23,"0.000")&"–"&TEXT('单机全档'!U23,"0.000") -> 2.470–2.522 | F27: =TEXT('单机全档'!V23,"0.000")&"–"&TEXT('单机全档'!W23,"0.000") -> 3.668–3.796 | G27: =TEXT('单机全档'!X23,"0.000")&"–"&TEXT('单机全档'!Y23,"0.000") -> 6.358–9.428 | H27: ='单机全档'!M23 -> 1 | I27: ='单机全档'!N23 -> 152.78192 | J27: =TEXT('单机全档'!Z23,"0.000")&"–"&TEXT('单机全档'!AA23,"0.000") -> -46.373–-46.298 | K27: =TEXT('单机全档'!AB23,"0.000")&"–"&TEXT('单机全档'!AC23,"0.000") -> -44.933–-44.806 | L27: =TEXT('单机全档'!AD23,"0.000")&"–"&TEXT('单机全档'!AE23,"0.000") -> -42.504–-40.683 | M27: 未测 | N27: 未测 | O27: 未测 | P27: =I27*'单机全档'!E23 -> 183338.31 | Q27: ='单机全档'!O23 -> 158.7625 | R27: =Q27*'单机全档'!E23 -> 190515
D28: 15000 | E28: =TEXT('单机全档'!T24,"0.000")&"–"&TEXT('单机全档'!U24,"0.000") -> 2.470–2.499 | F28: =TEXT('单机全档'!V24,"0.000")&"–"&TEXT('单机全档'!W24,"0.000") -> 3.746–3.831 | G28: =TEXT('单机全档'!X24,"0.000")&"–"&TEXT('单机全档'!Y24,"0.000") -> 8.656–11.791 | H28: ='单机全档'!M24 -> 1 | I28: ='单机全档'!N24 -> 229.16412 | J28: =TEXT('单机全档'!Z24,"0.000")&"–"&TEXT('单机全档'!AA24,"0.000") -> -46.281–-46.226 | K28: =TEXT('单机全档'!AB24,"0.000")&"–"&TEXT('单机全档'!AC24,"0.000") -> -44.802–-44.695 | L28: =TEXT('单机全档'!AD24,"0.000")&"–"&TEXT('单机全档'!AE24,"0.000") -> -40.916–-38.688 | M28: 未测 | N28: 未测 | O28: 未测 | P28: =I28*'单机全档'!E24 -> 274996.95 | Q28: ='单机全档'!O24 -> 238.12969 | R28: =Q28*'单机全档'!E24 -> 285755.62
D29: 18000 | E29: =TEXT('单机全档'!T25,"0.000")&"–"&TEXT('单机全档'!U25,"0.000") -> 2.467–2.498 | F29: =TEXT('单机全档'!V25,"0.000")&"–"&TEXT('单机全档'!W25,"0.000") -> 3.714–3.807 | G29: =TEXT('单机全档'!X25,"0.000")&"–"&TEXT('单机全档'!Y25,"0.000") -> 13.315–15.899 | H29: ='单机全档'!M25 -> 1 | I29: ='单机全档'!N25 -> 274.99328 | J29: =TEXT('单机全档'!Z25,"0.000")&"–"&TEXT('单机全档'!AA25,"0.000") -> -46.239–-46.195 | K29: =TEXT('单机全档'!AB25,"0.000")&"–"&TEXT('单机全档'!AC25,"0.000") -> -44.769–-44.666 | L29: =TEXT('单机全档'!AD25,"0.000")&"–"&TEXT('单机全档'!AE25,"0.000") -> -36.908–-34.703 | M29: 未测 | N29: 未测 | O29: 未测 | P29: =I29*'单机全档'!E25 -> 329991.94 | Q29: ='单机全档'!O25 -> 285.75625 | R29: =Q29*'单机全档'!E25 -> 342907.5
C30: 50 | D30: 1000 | E30: =TEXT('单机全档'!T26,"0.000")&"–"&TEXT('单机全档'!U26,"0.000") -> 3.303–3.521 | F30: =TEXT('单机全档'!V26,"0.000")&"–"&TEXT('单机全档'!W26,"0.000") -> 5.595–5.947 | G30: =TEXT('单机全档'!X26,"0.000")&"–"&TEXT('单机全档'!Y26,"0.000") -> 8.868–12.183 | H30: ='单机全档'!M26 -> 1 | I30: ='单机全档'!N26 -> 15.262397 | J30: =TEXT('单机全档'!Z26,"0.000")&"–"&TEXT('单机全档'!AA26,"0.000") -> -15.745–-15.467 | K30: =TEXT('单机全档'!AB26,"0.000")&"–"&TEXT('单机全档'!AC26,"0.000") -> -13.409–-13.022 | L30: =TEXT('单机全档'!AD26,"0.000")&"–"&TEXT('单机全档'!AE26,"0.000") -> -10.756–-6.671 | M30: 未测 | N30: 未测 | O30: 未测 | P30: =I30*'单机全档'!E26 -> 45787.19 | Q30: ='单机全档'!O26 -> 15.854687 | R30: =Q30*'单机全档'!E26 -> 47564.062
D31: 2000 | E31: =TEXT('单机全档'!T27,"0.000")&"–"&TEXT('单机全档'!U27,"0.000") -> 2.677–2.805 | F31: =TEXT('单机全档'!V27,"0.000")&"–"&TEXT('单机全档'!W27,"0.000") -> 3.874–4.203 | G31: =TEXT('单机全档'!X27,"0.000")&"–"&TEXT('单机全档'!Y27,"0.000") -> 5.961–8.950 | H31: ='单机全档'!M27 -> 1 | I31: ='单机全档'!N27 -> 30.514668 | J31: =TEXT('单机全档'!Z27,"0.000")&"–"&TEXT('单机全档'!AA27,"0.000") -> -16.024–-15.896 | K31: =TEXT('单机全档'!AB27,"0.000")&"–"&TEXT('单机全档'!AC27,"0.000") -> -14.493–-14.110 | L31: =TEXT('单机全档'!AD27,"0.000")&"–"&TEXT('单机全档'!AE27,"0.000") -> -12.243–-10.049 | M31: 未测 | N31: 未测 | O31: 未测 | P31: =I31*'单机全档'!E27 -> 91544.003 | Q31: ='单机全档'!O27 -> 31.704688 | R31: =Q31*'单机全档'!E27 -> 95114.062
D32: 5000 | E32: =TEXT('单机全档'!T28,"0.000")&"–"&TEXT('单机全档'!U28,"0.000") -> 1.932–1.986 | F32: =TEXT('单机全档'!V28,"0.000")&"–"&TEXT('单机全档'!W28,"0.000") -> 2.813–2.912 | G32: =TEXT('单机全档'!X28,"0.000")&"–"&TEXT('单机全档'!Y28,"0.000") -> 4.324–5.761 | H32: ='单机全档'!M28 -> 1 | I32: ='单机全档'!N28 -> 76.264756 | J32: =TEXT('单机全档'!Z28,"0.000")&"–"&TEXT('单机全档'!AA28,"0.000") -> -16.249–-16.143 | K32: =TEXT('单机全档'!AB28,"0.000")&"–"&TEXT('单机全档'!AC28,"0.000") -> -15.039–-14.866 | L32: =TEXT('单机全档'!AD28,"0.000")&"–"&TEXT('单机全档'!AE28,"0.000") -> -13.565–-12.872 | M32: 未测 | N32: 未测 | O32: 未测 | P32: =I32*'单机全档'!E28 -> 228794.27 | Q32: ='单机全档'!O28 -> 79.245312 | R32: =Q32*'单机全档'!E28 -> 237735.94
D33: 10000 | E33: =TEXT('单机全档'!T29,"0.000")&"–"&TEXT('单机全档'!U29,"0.000") -> 2.111–2.156 | F33: =TEXT('单机全档'!V29,"0.000")&"–"&TEXT('单机全档'!W29,"0.000") -> 3.099–3.225 | G33: =TEXT('单机全档'!X29,"0.000")&"–"&TEXT('单机全档'!Y29,"0.000") -> 10.432–17.093 | H33: ='单机全档'!M29 -> 1 | I33: ='单机全档'!N29 -> 152.51627 | J33: =TEXT('单机全档'!Z29,"0.000")&"–"&TEXT('单机全档'!AA29,"0.000") -> -16.026–-15.977 | K33: =TEXT('单机全档'!AB29,"0.000")&"–"&TEXT('单机全档'!AC29,"0.000") -> -14.717–-14.620 | L33: =TEXT('单机全档'!AD29,"0.000")&"–"&TEXT('单机全档'!AE29,"0.000") -> -10.559–-5.870 | M33: 未测 | N33: 未测 | O33: 未测 | P33: =I33*'单机全档'!E29 -> 457548.82 | Q33: ='单机全档'!O29 -> 158.475 | R33: =Q33*'单机全档'!E29 -> 475425
D34: 15000 | E34: =TEXT('单机全档'!T30,"0.000")&"–"&TEXT('单机全档'!U30,"0.000") -> 2.183–2.247 | F34: =TEXT('单机全档'!V30,"0.000")&"–"&TEXT('单机全档'!W30,"0.000") -> 4.472–5.863 | G34: =TEXT('单机全档'!X30,"0.000")&"–"&TEXT('单机全档'!Y30,"0.000") -> 28.763–47.275 | H34: ='单机全档'!M30 -> 1 | I34: ='单机全档'!N30 -> 228.77685 | J34: =TEXT('单机全档'!Z30,"0.000")&"–"&TEXT('单机全档'!AA30,"0.000") -> -15.968–-15.907 | K34: =TEXT('单机全档'!AB30,"0.000")&"–"&TEXT('单机全档'!AC30,"0.000") -> -13.526–-12.838 | L34: =TEXT('单机全档'!AD30,"0.000")&"–"&TEXT('单机全档'!AE30,"0.000") -> 6.748–13.209 | M34: 未测 | N34: 未测 | O34: 未测 | P34: =I34*'单机全档'!E30 -> 686330.55 | Q34: ='单机全档'!O30 -> 237.72813 | R34: =Q34*'单机全档'!E30 -> 713184.38
D35: 18000 | E35: =TEXT('单机全档'!T31,"0.000")&"–"&TEXT('单机全档'!U31,"0.000") -> 14.023–14.578 | F35: =TEXT('单机全档'!V31,"0.000")&"–"&TEXT('单机全档'!W31,"0.000") -> 30.288–32.228 | G35: =TEXT('单机全档'!X31,"0.000")&"–"&TEXT('单机全档'!Y31,"0.000") -> 79.456–105.608 | H35: ='单机全档'!M31 -> 1 | I35: ='单机全档'!N31 -> 274.34813 | J35: =TEXT('单机全档'!Z31,"0.000")&"–"&TEXT('单机全档'!AA31,"0.000") -> 2.241–2.912 | K35: =TEXT('单机全档'!AB31,"0.000")&"–"&TEXT('单机全档'!AC31,"0.000") -> 21.574–23.412 | L35: =TEXT('单机全档'!AD31,"0.000")&"–"&TEXT('单机全档'!AE31,"0.000") -> 52.705–68.246 | M35: 未测 | N35: 未测 | O35: 未测 | P35: =I35*'单机全档'!E31 -> 823044.39 | Q35: ='单机全档'!O31 -> 285.07812 | R35: =Q35*'单机全档'!E31 -> 855234.37
C36: 100 | D36: 1000 | E36: =TEXT('单机全档'!T32,"0.000")&"–"&TEXT('单机全档'!U32,"0.000") -> 2.768–2.861 | F36: =TEXT('单机全档'!V32,"0.000")&"–"&TEXT('单机全档'!W32,"0.000") -> 3.948–4.143 | G36: =TEXT('单机全档'!X32,"0.000")&"–"&TEXT('单机全档'!Y32,"0.000") -> 5.630–8.769 | H36: ='单机全档'!M32 -> 1 | I36: ='单机全档'!N32 -> 15.245725 | J36: =TEXT('单机全档'!Z32,"0.000")&"–"&TEXT('单机全档'!AA32,"0.000") -> -5.433–-4.968 | K36: =TEXT('单机全档'!AB32,"0.000")&"–"&TEXT('单机全档'!AC32,"0.000") -> -3.419–-2.615 | L36: =TEXT('单机全档'!AD32,"0.000")&"–"&TEXT('单机全档'!AE32,"0.000") -> -1.235–1.716 | M36: 未测 | N36: 未测 | O36: 未测 | P36: =I36*'单机全档'!E32 -> 91474.353 | Q36: ='单机全档'!O32 -> 15.8375 | R36: =Q36*'单机全档'!E32 -> 95025
D37: 2000 | E37: =TEXT('单机全档'!T33,"0.000")&"–"&TEXT('单机全档'!U33,"0.000") -> 2.078–2.183 | F37: =TEXT('单机全档'!V33,"0.000")&"–"&TEXT('单机全档'!W33,"0.000") -> 3.079–3.274 | G37: =TEXT('单机全档'!X33,"0.000")&"–"&TEXT('单机全档'!Y33,"0.000") -> 4.585–7.179 | H37: ='单机全档'!M33 -> 1 | I37: ='单机全档'!N33 -> 30.475973 | J37: =TEXT('单机全档'!Z33,"0.000")&"–"&TEXT('单机全档'!AA33,"0.000") -> -5.603–-5.257 | K37: =TEXT('单机全档'!AB33,"0.000")&"–"&TEXT('单机全档'!AC33,"0.000") -> -3.874–-3.155 | L37: =TEXT('单机全档'!AD33,"0.000")&"–"&TEXT('单机全档'!AE33,"0.000") -> -2.251–0.035 | M37: 未测 | N37: 未测 | O37: 未测 | P37: =I37*'单机全档'!E33 -> 182855.84 | Q37: ='单机全档'!O33 -> 31.659375 | R37: =Q37*'单机全档'!E33 -> 189956.25
D38: 5000 | E38: =TEXT('单机全档'!T34,"0.000")&"–"&TEXT('单机全档'!U34,"0.000") -> 2.053–2.117 | F38: =TEXT('单机全档'!V34,"0.000")&"–"&TEXT('单机全档'!W34,"0.000") -> 2.811–2.897 | G38: =TEXT('单机全档'!X34,"0.000")&"–"&TEXT('单机全档'!Y34,"0.000") -> 5.568–8.912 | H38: ='单机全档'!M34 -> 1 | I38: ='单机全档'!N34 -> 76.142619 | J38: =TEXT('单机全档'!Z34,"0.000")&"–"&TEXT('单机全档'!AA34,"0.000") -> -5.567–-5.272 | K38: =TEXT('单机全档'!AB34,"0.000")&"–"&TEXT('单机全档'!AC34,"0.000") -> -3.707–-3.543 | L38: =TEXT('单机全档'!AD34,"0.000")&"–"&TEXT('单机全档'!AE34,"0.000") -> -1.868–-0.017 | M38: 未测 | N38: 未测 | O38: 未测 | P38: =I38*'单机全档'!E34 -> 456855.71 | Q38: ='单机全档'!O34 -> 79.11875 | R38: =Q38*'单机全档'!E34 -> 474712.5
D39: 10000 | E39: =TEXT('单机全档'!T35,"0.000")&"–"&TEXT('单机全档'!U35,"0.000") -> 6.837–7.767 | F39: =TEXT('单机全档'!V35,"0.000")&"–"&TEXT('单机全档'!W35,"0.000") -> 19.510–24.685 | G39: =TEXT('单机全档'!X35,"0.000")&"–"&TEXT('单机全档'!Y35,"0.000") -> 60.650–70.644 | H39: ='单机全档'!M35 -> 1 | I39: ='单机全档'!N35 -> 152.23858 | J39: =TEXT('单机全档'!Z35,"0.000")&"–"&TEXT('单机全档'!AA35,"0.000") -> 1.908–2.627 | K39: =TEXT('单机全档'!AB35,"0.000")&"–"&TEXT('单机全档'!AC35,"0.000") -> 15.002–18.215 | L39: =TEXT('单机全档'!AD35,"0.000")&"–"&TEXT('单机全档'!AE35,"0.000") -> 39.723–50.769 | M39: 未测 | N39: 未测 | O39: 未测 | P39: =I39*'单机全档'!E35 -> 913431.48 | Q39: ='单机全档'!O35 -> 158.19219 | R39: =Q39*'单机全档'!E35 -> 949153.13
D40: 15000 | E40: =TEXT('单机全档'!T36,"0.000")&"–"&TEXT('单机全档'!U36,"0.000") -> 23.683–28.679 | F40: =TEXT('单机全档'!V36,"0.000")&"–"&TEXT('单机全档'!W36,"0.000") -> 83.969–103.768 | G40: =TEXT('单机全档'!X36,"0.000")&"–"&TEXT('单机全档'!Y36,"0.000") -> 132.249–184.997 | H40: ='单机全档'!M36 -> 1 | I40: ='单机全档'!N36 -> 227.70103 | J40: =TEXT('单机全档'!Z36,"0.000")&"–"&TEXT('单机全档'!AA36,"0.000") -> 26.032–31.648 | K40: =TEXT('单机全档'!AB36,"0.000")&"–"&TEXT('单机全档'!AC36,"0.000") -> 104.289–126.037 | L40: =TEXT('单机全档'!AD36,"0.000")&"–"&TEXT('单机全档'!AE36,"0.000") -> 318.567–364.845 | M40: 未测 | N40: 未测 | O40: 未测 | P40: =I40*'单机全档'!E36 -> 1366206.2 | Q40: ='单机全档'!O36 -> 236.57812 | R40: =Q40*'单机全档'!E36 -> 1419468.7
...

Sheet 单机全档
A1: 组 | B1: 输出阶段时长s | C1: 稳态s | D1: 设定单流tok/s | E1: 每请求输出token | F1: 理想token间隔ms | G1: 模板理想总流时长ms | H1: VUS | I1: 请求数 | J1: 体采样数 | K1: 实际体采样比例 | L1: 设定体采样比例 | M1: 请求成功率 | N1: 整轮RPS | O1: 稳态成功RPS | P1: 整轮输出TPS | Q1: 稳态输出TPS | R1: 整轮输出TPM | S1: 稳态输出TPM | T1: TTFT-500 P50下界ms | U1: TTFT-500 P50上界ms | V1: TTFT-500 P90下界ms | W1: TTFT-500 P90上界ms | X1: TTFT-500 P99下界ms | Y1: TTFT-500 P99上界ms | Z1: 流时长-理论 P50下界ms | AA1: 流时长-理论 P50上界ms | AB1: 流时长-理论 P90下界ms | AC1: 流时长-理论 P90上界ms | AD1: 流时长-理论 P99下界ms | AE1: 流时长-理论 P99上界ms | AF1: mock生成批间隔差 P50下界ms | AG1: mock生成批间隔差 P50上界ms | AH1: mock生成批间隔差 P90下界ms | AI1: mock生成批间隔差 P90上界ms | AJ1: mock生成批间隔差 P99下界ms | AK1: mock生成批间隔差 P99上界ms | AL1: TTFT加权均值ms | AM1: HTTP流时长加权均值ms | AN1: 迭代时长加权均值ms | AO1: 估算活跃流 | AP1: 执行批次 | AQ1: k6内存软限制 | AR1: 原始阶段标识 | AS1: 网络接收批间隔P50 | AT1: 网络接收批间隔P90 | AU1: 网络接收批间隔P99
A2: A | B2: 5 | C2: 300 | D2: =1000/F2 -> 20 | E2: 100 | F2: 50 | G2: =500+E2*F2 -> 5500 | H2: 1000 | I2: 58236 | J2: 29006 | K2: =J2/I2 -> 0.49807679 | L2: 0.5 | M2: 1 | N2: 173.63295 | O2: 183.24 | P2: =N2*E2 -> 17363.295 | Q2: =O2*E2 -> 18324 | R2: =P2*60 -> 1041797.7 | S2: =Q2*60 -> 1099440 | T2: 4.442813 | U2: 4.789853 | V2: 11.228259 | W2: 12.417436 | X2: 20.392393 | Y2: 22.275178 | Z2: -45.666806 | AA2: -45.411775 | AB2: -40.437861 | AC2: -39.832341 | AD2: -32.526682 | AE2: -30.78586 | AF2: 0 | AG2: 0 | AH2: 1 | AI2: 1 | AJ2: 1 | AK2: 1 | AL2: 506.01926 | AM2: 5455.5069 | AN2: 5457.9988 | AO2: 999.54343 | AP2: r10 | AQ2: 未设软限制 | AR2: formal-xlite-A-1000 | AS2: 未测 | AT2: 未测 | AU2: 未测
A3: A | B3: 5 | C3: 300 | D3: =1000/F3 -> 20 | E3: 100 | F3: 50 | G3: =500+E3*F3 -> 5500 | H3: 2000 | I3: 116484 | J3: 58268 | K3: =J3/I3 -> 0.50022321 | L3: 0.5 | M3: 1 | N3: 347.28297 | O3: 366.46667 | P3: =N3*E3 -> 34728.297 | Q3: =O3*E3 -> 36646.667 | R3: =P3*60 -> 2083697.8 | S3: =Q3*60 -> 2198800 | T3: 3.449453 | U3: 3.5352 | V3: 6.315259 | W3: 6.4873896 | X3: 9.5442089 | Y3: 10.323965 | Z3: -46.241764 | AA3: -46.163991 | AB3: -43.49574 | AC3: -43.280865 | AD3: -40.675334 | AE3: -39.988903 | AF3: 0 | AG3: 0 | AH3: 1 | AI3: 1 | AJ3: 1 | AK3: 1 | AL3: 503.93894 | AM3: 5454.2493 | AN3: 5456.7982 | AO3: 1999.0658 | AP3: r10 | AQ3: 未设软限制 | AR3: formal-xlite-A-2000 | AS3: 未测 | AT3: 未测 | AU3: 未测
A4: A | B4: 5 | C4: 300 | D4: =1000/F4 -> 20 | E4: 100 | F4: 50 | G4: =500+E4*F4 -> 5500 | H4: 5000 | I4: 291271 | J4: 145973 | K4: =J4/I4 -> 0.50115871 | L4: 0.5 | M4: 1 | N4: 868.30822 | O4: 916.36333 | P4: =N4*E4 -> 86830.822 | Q4: =O4*E4 -> 91636.333 | R4: =P4*60 -> 5209849.3 | S4: =Q4*60 -> 5498180 | T4: 2.534359 | U4: 2.57448 | V4: 3.7387549 | W4: 3.8038128 | X4: 5.2438876 | Y4: 5.5528768 | Z4: -46.751516 | AA4: -46.71157 | AB4: -45.379486 | AC4: -45.291686 | AD4: -43.811202 | AE4: -43.57645 | AF4: 0 | AG4: 0 | AH4: 1 | AI4: 1 | AJ4: 1 | AK4: 1 | AL4: 502.65528 | AM4: 5453.4538 | AN4: 5456.1559 | AO4: 4997.5238 | AP4: r10 | AQ4: 未设软限制 | AR4: formal-xlite-A-5000 | AS4: 未测 | AT4: 未测 | AU4: 未测
A5: A | B5: 5 | C5: 300 | D5: =1000/F5 -> 20 | E5: 100 | F5: 50 | G5: =500+E5*F5 -> 5500 | H5: 10000 | I5: 582513 | J5: 291118 | K5: =J5/I5 -> 0.49976224 | L5: 0.5 | M5: 1 | N5: 1736.442 | O5: 1832.64 | P5: =N5*E5 -> 173644.2 | Q5: =O5*E5 -> 183264 | R5: =P5*60 -> 10418652 | S5: =Q5*60 -> 10995840 | T5: 2.3898445 | U5: 2.411355 | V5: 3.5459912 | W5: 3.5943342 | X5: 5.2697702 | Y5: 5.6327045 | Z5: -46.702882 | AA5: -46.665883 | AB5: -45.35117 | AC5: -45.304514 | AD5: -43.63954 | AE5: -43.464751 | AF5: 0 | AG5: 0 | AH5: 1 | AI5: 1 | AJ5: 1 | AK5: 1 | AL5: 502.50736 | AM5: 5453.5026 | AN5: 5456.3748 | AO5: 9994.736 | AP5: r10 | AQ5: 未设软限制 | AR5: formal-xlite-A-10000 | AS5: 未测 | AT5: 未测 | AU5: 未测
A6: A | B6: 5 | C6: 300 | D6: =1000/F6 -> 20 | E6: 100 | F6: 50 | G6: =500+E6*F6 -> 5500 | H6: 15000 | I6: 873700 | J6: 436495 | K6: =J6/I6 -> 0.49959368 | L6: 0.5 | M6: 1 | N6: 2604.4613 | O6: 2748.8033 | P6: =N6*E6 -> 260446.13 | Q6: =O6*E6 -> 274880.33 | R6: =P6*60 -> 15626768 | S6: =Q6*60 -> 16492820 | T6: 2.369801 | U6: 2.40215 | V6: 3.5882337 | W6: 3.643047 | X6: 6.0859108 | Y6: 6.4273486 | Z6: -46.619868 | AA6: -46.584942 | AB6: -45.230091 | AC6: -45.173886 | AD6: -42.941072 | AE6: -42.539066 | AF6: 0 | AG6: 0 | AH6: 1 | AI6: 1 | AJ6: 1 | AK6: 1 | AL6: 502.61023 | AM6: 5453.6764 | AN6: 5456.6654 | AO6: 14991.783 | AP6: r10 | AQ6: 未设软限制 | AR6: formal-xlite-A-15000 | AS6: 未测 | AT6: 未测 | AU6: 未测
A7: A | B7: 5 | C7: 300 | D7: =1000/F7 -> 20 | E7: 100 | F7: 50 | G7: =500+E7*F7 -> 5500 | H7: 18000 | I7: 1048413 | J7: 525024 | K7: =J7/I7 -> 0.50077975 | L7: 0.5 | M7: 1 | N7: 3125.2536 | O7: 3298.3967 | P7: =N7*E7 -> 312525.36 | Q7: =O7*E7 -> 329839.67 | R7: =P7*60 -> 18751522 | S7: =Q7*60 -> 19790380 | T7: 2.3665575 | U7: 2.393591 | V7: 3.5316335 | W7: 3.5739516 | X7: 8.3476778 | Y7: 9.5211176 | Z7: -46.576436 | AA7: -46.543832 | AB7: -45.233411 | AC7: -45.167833 | AD7: -41.160211 | AE7: -40.04808 | AF7: 0 | AG7: 0 | AH7: 1 | AI7: 1 | AJ7: 1 | AK7: 1 | AL7: 502.6796 | AM7: 5453.7958 | AN7: 5456.8771 | AO7: 17989.836 | AP7: r10 | AQ7: 未设软限制 | AR7: formal-xlite-A-18000 | AS7: 未测 | AT7: 未测 | AU7: 未测
A8: E | B8: 5 | C8: 300 | D8: =1000/F8 -> 50 | E8: 250 | F8: 20 | G8: =500+E8*F8 -> 5500 | H8: 1000 | I8: 57882 | J8: 28781 | K8: =J8/I8 -> 0.49723576 | L8: 0.5 | M8: 1 | N8: 172.55178 | O8: 182.09 | P8: =N8*E8 -> 43137.946 | Q8: =O8*E8 -> 45522.5 | R8: =P8*60 -> 2588276.7 | S8: =Q8*60 -> 2731350 | T8: 3.250344 | U8: 3.357294 | V8: 5.5682645 | W8: 5.838872 | X8: 8.166721 | Y8: 9.0748616 | Z8: -16.369404 | AA8: -16.195351 | AB8: -14.068673 | AC8: -13.818035 | AD8: -11.514079 | AE8: -10.791716 | AF8: 0 | AG8: 0 | AH8: 1 | AI8: 1 | AJ8: 1 | AK8: 1 | AL8: 503.66574 | AM8: 5484.0558 | AN8: 5488.743 | AO8: 999.14605 | AP8: r10 | AQ8: 未设软限制 | AR8: formal-xlite-E-1000 | AS8: 未测 | AT8: 未测 | AU8: 未测
A9: E | B9: 5 | C9: 300 | D9: =1000/F9 -> 50 | E9: 250 | F9: 20 | G9: =500+E9*F9 -> 5500 | H9: 2000 | I9: 115770 | J9: 57896 | K9: =J9/I9 -> 0.50009502 | L9: 0.5 | M9: 1 | N9: 345.10598 | O9: 364.18667 | P9: =N9*E9 -> 86276.496 | Q9: =O9*E9 -> 91046.667 | R9: =P9*60 -> 5176589.8 | S9: =Q9*60 -> 5462800 | T9: 2.630545 | U9: 2.666674 | V9: 3.8248905 | W9: 3.9154686 | X9: 5.3089272 | Y9: 5.6381798 | Z9: -16.695598 | AA9: -16.654406 | AB9: -15.30364 | AC9: -15.210337 | AD9: -13.817454 | AE9: -13.554045 | AF9: 0 | AG9: 0 | AH9: 1 | AI9: 1 | AJ9: 1 | AK9: 1 | AL9: 502.74195 | AM9: 5483.505 | AN9: 5488.3959 | AO9: 1998.2177 | AP9: r10 | AQ9: 未设软限制 | AR9: formal-xlite-E-2000 | AS9: 未测 | AT9: 未测 | AU9: 未测
A10: E | B10: 5 | C10: 300 | D10: =1000/F10 -> 50 | E10: 250 | F10: 20 | G10: =500+E10*F10 -> 5500 | H10: 5000 | I10: 289412 | J10: 145037 | K10: =J10/I10 -> 0.5011437 | L10: 0.5 | M10: 1 | N10: 862.67964 | O10: 910.45333 | P10: =N10*E10 -> 215669.91 | Q10: =O10*E10 -> 227613.33 | R10: =P10*60 -> 12940195 | S10: =Q10*60 -> 13656800 | T10: 1.8431825 | U10: 1.87363 | V10: 2.7168037 | W10: 2.7705504 | X10: 3.6745856 | Y10: 3.799269 | Z10: -16.953928 | AA10: -16.913626 | AB10: -16.037043 | AC10: -15.973633 | AD10: -14.86639 | AE10: -14.612444 | AF10: 0 | AG10: 0 | AH10: 1 | AI10: 1 | AJ10: 1 | AK10: 1 | AL10: 501.98247 | AM10: 5483.204 | AN10: 5488.5462 | AO10: 4995.1332 | AP10: r10 | AQ10: 未设软限制 | AR10: formal-xlite-E-5000 | AS10: 未测 | AT10: 未测 | AU10: 未测
A11: E | B11: 5 | C11: 300 | D11: =1000/F11 -> 50 | E11: 250 | F11: 20 | G11: =500+E11*F11 -> 5500 | H11: 10000 | I11: 578726 | J11: 289708 | K11: =J11/I11 -> 0.50059614 | L11: 0.5 | M11: 1 | N11: 1725.0116 | O11: 1820.6033 | P11: =N11*E11 -> 431252.9 | Q11: =O11*E11 -> 455150.83 | R11: =P11*60 -> 25875174 | S11: =Q11*60 -> 27309050 | T11: 2.010527 | U11: 2.040447 | V11: 2.9179833 | W11: 2.9773778 | X11: 4.8049375 | Y11: 5.6689775 | Z11: -16.728414 | AA11: -16.688133 | AB11: -15.703876 | AC11: -15.646371 | AD11: -13.480251 | AE11: -12.580863 | AF11: 0 | AG11: 0 | AH11: 1 | AI11: 1 | AJ11: 1 | AK11: 1 | AL11: 502.22997 | AM11: 5483.5192 | AN11: 5489.3012 | AO11: 9989.4667 | AP11: r10 | AQ11: 未设软限制 | AR11: formal-xlite-E-10000 | AS11: 未测 | AT11: 未测 | AU11: 未测
A12: E | B12: 5 | C12: 300 | D12: =1000/F12 -> 50 | E12: 250 | F12: 20 | G12: =500+E12*F12 -> 5500 | H12: 15000 | I12: 868098 | J12: 434581 | K12: =J12/I12 -> 0.50061283 | L12: 0.5 | M12: 1 | N12: 2587.4809 | O12: 2731.08 | P12: =N12*E12 -> 646870.21 | Q12: =O12*E12 -> 682770 | R12: =P12*60 -> 38812213 | S12: =Q12*60 -> 40966200 | T12: 2.083792 | U12: 2.108976 | V12: 3.253448 | W12: 3.344605 | X12: 10.255934 | Y12: 12.186944 | Z12: -16.590957 | AA12: -16.554065 | AB12: -15.208333 | AC12: -15.08883 | AD12: -8.4109758 | AE12: -6.5757857 | AF12: 0 | AG12: 0 | AH12: 1 | AI12: 1 | AJ12: 1 | AK12: 1 | AL12: 502.57115 | AM12: 5483.9169 | AN12: 5489.4624 | AO12: 14984.847 | AP12: r10 | AQ12: 未设软限制 | AR12: formal-xlite-E-15000 | AS12: 未测 | AT12: 未测 | AU12: 未测
A13: E | B13: 5 | C13: 300 | D13: =1000/F13 -> 50 | E13: 250 | F13: 20 | G13: =500+E13*F13 -> 5500 | H13: 18000 | I13: 1041770 | J13: 521262 | K13: =J13/I13 -> 0.50036188 | L13: 0.5 | M13: 1 | N13: 3105.1143 | O13: 3277.36 | P13: =N13*E13 -> 776278.57 | Q13: =O13*E13 -> 819340 | R13: =P13*60 -> 46576714 | S13: =Q13*60 -> 49160400 | T13: 2.122797 | U13: 2.153697 | V13: 3.9302519 | W13: 4.1967342 | X13: 15.728751 | Y13: 19.31364 | Z13: -16.494645 | AA13: -16.459795 | AB13: -14.195406 | AC13: -13.849264 | AD13: -2.4046079 | AE13: -0.63170622 | AF13: 0 | AG13: 0 | AH13: 1 | AI13: 1 | AJ13: 1 | AK13: 1 | AL13: 502.98326 | AM13: 5484.4161 | AN13: 5489.3555 | AO13: 17983.803 | AP13: r10 | AQ13: 未设软限制 | AR13: formal-xlite-E-18000 | AS13: 未测 | AT13: 未测 | AU13: 未测
... A37: D | B37: 60 | C37: 640 | D37: =1000/F37 -> 100 | E37: 6000 | F37: 10 | G37: =500+E37*F37 -> 60500 | H37: 18000 | I37: 198969 | J37: 99710 | K37: =J37/I37 -> 0.50113334 | L37: 0.5 | M37: 1 | N37: 272.34601 | O37: 282.86719 | P37: =N37*E37 -> 1634076 | Q37: =O37*E37 -> 1697203.1 | R37: =P37*60 -> 98044563 | S37: =Q37*60 -> 1.0183219e+08 | T37: 53.955993 | U37: 80.837988 | V37: 127.10262 | W37: 234.48798 | X37: 224.45448 | Y37: 480.53214 | Z37: 58.804665 | AA37: 73.889665 | AB37: 255.84148 | AC37: 314.31522 | AD37: 703.56437 | AE37: 803.96671 | AF37: 0 | AG37: 0 | AH37: 1 | AI37: 1 | AJ37: 1 | AK37: 1 | AL37: 580.57771 | AM37: 60616.635 | AN37: 60896.72 | AO37: 17917.238 | AP37: r11 | AQ37: 9GiB/片 | AR37: formal-xlite-D-18000 | AS37: 未测 | AT37: 未测 | AU37: 未测

Sheet 分片原始指标
A1: 产品 | B1: 组 | C1: VUS | D1: 执行批次 | E1: 分片 | F1: 分片最大VUS | G1: 请求数 | H1: 体采样数 | I1: 稳态成功请求数 | J1: HTTP失败比例 | K1: TTFT P50ms | L1: TTFT P90ms | M1: TTFT P99ms | N1: HTTP流时长P50ms | O1: HTTP流时长P90ms | P1: HTTP流时长P99ms | Q1: mock生成间隔P50ms | R1: mock生成间隔P90ms | S1: mock生成间隔P99ms | T1: TTFT均值ms | U1: HTTP流时长均值ms | V1: 迭代时长均值ms | W1: 体校验错误 | X1: 传输错误 | Y1: 非200 | Z1: 原始摘要相对路径 | AA1: 摘要SHA256
A2: xrouter | B2: A | C2: 1000 | D2: r10 | E2: 0 | F2: 63 | G2: 3669 | H2: 1804 | I2: 3463 | J2: 0 | K2: 504.69613 | L2: 511.64886 | M2: 521.09475 | N2: 5454.4291 | O2: 5459.7816 | P2: 5468.5208 | Q2: 50 | R2: 51 | S2: 51 | T2: 506.0122 | U2: 5455.4641 | V2: 5457.8886 | W2: 0 | X2: 0 | Y2: 0 | Z2: raw/assembled/sources/r10/results/formal-xlite-A-1000.shard-0.summary.json | AA2: 9be4031632354966b0990c3e1895db5c60635006726234570252174ecb041a16
A3: xrouter | B3: A | C3: 1000 | D3: r10 | E3: 1 | F3: 63 | G3: 3668 | H3: 1866 | I3: 3462 | J3: 0 | K3: 504.58659 | L3: 511.76167 | M3: 521.11478 | N3: 5454.5882 | O3: 5459.8111 | P3: 5468.1883 | Q3: 50 | R3: 51 | S3: 51 | T3: 505.95415 | U3: 5455.5649 | V3: 5458.1218 | W3: 0 | X3: 0 | Y3: 0 | Z3: raw/assembled/sources/r10/results/formal-xlite-A-1000.shard-1.summary.json | AA3: 7c41efe263fc5ad225aac963bc2f13ef2296250443a43debf1199a72edf6b1cf
A4: xrouter | B4: A | C4: 1000 | D4: r10 | E4: 2 | F4: 63 | G4: 3669 | H4: 1807 | I4: 3463 | J4: 0 | K4: 504.56934 | L4: 511.9533 | M4: 520.79705 | N4: 5454.3789 | O4: 5459.9142 | P4: 5468.4398 | Q4: 50 | R4: 51 | S4: 51 | T4: 505.96798 | U4: 5455.4901 | V4: 5457.9956 | W4: 0 | X4: 0 | Y4: 0 | Z4: raw/assembled/sources/r10/results/formal-xlite-A-1000.shard-2.summary.json | AA4: 39327d64f9a1a5e2b0060bc0f2bfae762ed9a3936d3e391234661f0f113deb1c
A5: xrouter | B5: A | C5: 1000 | D5: r10 | E5: 3 | F5: 63 | G5: 3668 | H5: 1839 | I5: 3462 | J5: 0 | K5: 504.76979 | L5: 512.28354 | M5: 521.661 | N5: 5454.518 | O5: 5460.0522 | P5: 5469.0131 | Q5: 50 | R5: 51 | S5: 51 | T5: 506.17657 | U5: 5455.5661 | V5: 5458.0943 | W5: 0 | X5: 0 | Y5: 0 | Z5: raw/assembled/sources/r10/results/formal-xlite-A-1000.shard-3.summary.json | AA5: 24f46fced2fc542b41d3fcac7b1efd5d7751f84b203285ff6be2984dbc4f7bc4
A6: xrouter | B6: A | C6: 1000 | D6: r10 | E6: 4 | F6: 63 | G6: 3668 | H6: 1772 | I6: 3462 | J6: 0 | K6: 504.44281 | L6: 511.22826 | M6: 521.6126 | N6: 5454.5402 | O6: 5459.7062 | P6: 5468.4013 | Q6: 50 | R6: 51 | S6: 51 | T6: 505.83275 | U6: 5455.5065 | V6: 5457.9422 | W6: 0 | X6: 0 | Y6: 0 | Z6: raw/assembled/sources/r10/results/formal-xlite-A-1000.shard-4.summary.json | AA6: c5fa3d45e029a6f2a1538ddafff209f1627382e3ee30f22fdb5637b2be631b28
A7: xrouter | B7: A | C7: 1000 | D7: r10 | E7: 5 | F7: 63 | G7: 3669 | H7: 1847 | I7: 3463 | J7: 0 | K7: 504.78985 | L7: 511.84905 | M7: 521.73437 | N7: 5454.4552 | O7: 5459.7811 | P7: 5468.0446 | Q7: 50 | R7: 51 | S7: 51 | T7: 506.07754 | U7: 5455.4677 | V7: 5457.9536 | W7: 0 | X7: 0 | Y7: 0 | Z7: raw/assembled/sources/r10/results/formal-xlite-A-1000.shard-5.summary.json | AA7: f95312bcb8a52526cae8cc8b418051ab1a34e79f6b2847ae4b812a2bca35a68a
A8: xrouter | B8: A | C8: 1000 | D8: r10 | E8: 6 | F8: 63 | G8: 3668 | H8: 1866 | I8: 3462 | J8: 0 | K8: 504.7519 | L8: 512.24824 | M8: 520.70111 | N8: 5454.4654 | O8: 5459.906 | P8: 5468.5475 | Q8: 50 | R8: 51 | S8: 51 | T8: 506.11362 | U8: 5455.5058 | V8: 5458.0386 | W8: 0 | X8: 0 | Y8: 0 | Z8: raw/assembled/sources/r10/results/formal-xlite-A-1000.shard-6.summary.json | AA8: 0a4e22a38610a89d9e4d6aefb38f30128d3fe15856f595401cfd458cba3228a9
A9: xrouter | B9: A | C9: 1000 | D9: r10 | E9: 7 | F9: 63 | G9: 3669 | H9: 1820 | I9: 3463 | J9: 0 | K9: 504.77839 | L9: 512.2667 | M9: 522.22067 | N9: 5454.5221 | O9: 5460.1291 | P9: 5469.2141 | Q9: 50 | R9: 51 | S9: 51 | T9: 506.16445 | U9: 5455.6012 | V9: 5458.1136 | W9: 0 | X9: 0 | Y9: 0 | Z9: raw/assembled/sources/r10/results/formal-xlite-A-1000.shard-7.summary.json | AA9: eacd7cb62602f00befb0ee0bb61c2f4282787c36fcbb36fa5c5dd5382ef4b372
A10: xrouter | B10: A | C10: 1000 | D10: r10 | E10: 8 | F10: 62 | G10: 3611 | H10: 1767 | I10: 3409 | J10: 0 | K10: 504.52984 | L10: 511.80779 | M10: 521.28082 | N10: 5454.383 | O10: 5459.77 | P10: 5467.8215 | Q10: 50 | R10: 51 | S10: 51 | T10: 505.90081 | U10: 5455.4818 | V10: 5457.9438 | W10: 0 | X10: 0 | Y10: 0 | Z10: raw/assembled/sources/r10/results/formal-xlite-A-1000.shard-8.summary.json | AA10: 5310885f5281b8f866cafa52e5df63ea8ed575995bb62b5a87b0f4ccc7af4c44
A11: xrouter | B11: A | C11: 1000 | D11: r10 | E11: 9 | F11: 62 | G11: 3611 | H11: 1814 | I11: 3409 | J11: 0 | K11: 504.64645 | L11: 511.67992 | M11: 521.27379 | N11: 5454.5277 | O11: 5459.7133 | P11: 5467.4733 | Q11: 50 | R11: 51 | S11: 51 | T11: 505.94822 | U11: 5455.4671 | V11: 5457.9614 | W11: 0 | X11: 0 | Y11: 0 | Z11: raw/assembled/sources/r10/results/formal-xlite-A-1000.shard-9.summary.json | AA11: 6c3c528e14cde1560861c805185efdc44c859b3e8bc1b2a5393a5d8395d3f61d
A12: xrouter | B12: A | C12: 1000 | D12: r10 | E12: 10 | F12: 62 | G12: 3611 | H12: 1774 | I12: 3409 | J12: 0 | K12: 504.75353 | L12: 511.80113 | M12: 521.45379 | N12: 5454.4805 | O12: 5460.0344 | P12: 5468.9454 | Q12: 50 | R12: 51 | S12: 51 | T12: 506.06918 | U12: 5455.5449 | V12: 5458.0627 | W12: 0 | X12: 0 | Y12: 0 | Z12: raw/assembled/sources/r10/results/formal-xlite-A-1000.shard-10.summary.json | AA12: 1ea98c1b7b173da7da7b02bc1d02c4eea6ce139126cd2e134c4f5bc7c9c9a60f
A13: xrouter | B13: A | C13: 1000 | D13: r10 | E13: 11 | F13: 62 | G13: 3611 | H13: 1822 | I13: 3409 | J13: 0 | K13: 504.71984 | L13: 512.41744 | M13: 521.60726 | N13: 5454.4517 | O13: 5459.911 | P13: 5468.5154 | Q13: 50 | R13: 51 | S13: 51 | T13: 506.15916 | U13: 5455.5371 | V13: 5458.0749 | W13: 0 | X13: 0 | Y13: 0 | Z13: raw/assembled/sources/r10/results/formal-xlite-A-1000.shard-11.summary.json | AA13: 83d3cbba39f5750ea3262462aeb867f95a42c4768e4141f1ee774a008ad7c9f8
... A577: xrouter | B577: D | C577: 18000 | D577: r11 | E577: 15 | F577: 1125 | G577: 12444 | H577: 6250 | I577: 11323 | J577: 0 | K577: 574.28261 | L577: 710.97917 | M577: 841.243 | N577: 60568.397 | O577: 60787.711 | P577: 61268.098 | Q577: 10 | R577: 11 | S577: 11 | T577: 593.28742 | U577: 60621.166 | V577: 60962.45 | W577: 0 | X577: 0 | Y577: 0 | Z577: raw/assembled/sources/r11/results/formal-xlite-D-18000.shard-15.summary.json | AA577: 1338787ab02cb47818e970dbeb279b3b1b23c5f62984a036938e979917dd6901

Sheet 指标定义与口径
A1: 项目 | B1: 数值/公式 | C1: 说明
A2: 产品 | B2: xrouter | C2: 仅报告展示名改变；原测试二进制名xlite，源证据文件名不改。
A3: 数据范围 | B3: 单机6组×6档，共36正式阶段 | C3: A/E/B为5s输出，C/F/D为60s输出；每组1k、2k、5k、10k、15k、18k。
A4: 单流tok/s | B4: 1000 / 每token间隔ms | C4: 20对应A/C；50对应E/F；100对应B/D。配置速率，不是系统吞吐。
A5: 总输出TPS | B5: 成功RPS × 每请求输出token | C5: batch=1的mock约定token；不是生产模型实测分词速度。
A6: TPM | B6: 输出TPS × 60 | C6: 整轮/稳态TPM在全档表分别给出。
A7: TTFT超出固定等待 | B7: TTFT分片P50/P90/P99 − 500ms | C7: 没有测净网关TTFT；包括mock调度、网络、客户端、网关等。
A8: 流时长减理论值 | B8: HTTP流时长分位数 − (500+输出token×间隔ms) | C8: 遵从原模板；首帧后实际通常只有输出token−1个间隔，负值保留。
A9: 网络接收批间隔 | B9: 未测 | C9: 当前k6在完成后分析体，没有逐网络帧到达时刻，不能填网关批间隔时延。
A10: mock生成间隔 | B10: chunk_interval_ms − 配置间隔ms | C10: 从mock帧内生成时间戳计算，最多64个均匀间隔点/样本，非网络到达间隔。
A11: 分位数 | B11: 16个分片分位数的最小–最大 | C11: 不能对分片分位数取平均冒充总体分位数；全档表提供可计算的数值上下界。
A12: 平均RPS | B12: 整轮完成请求数 / 原统计时间 | C12: 包括爬坡与收尾，主表另列稳态成功RPS，不能混用。
... A19: 版本 | B19: ad4e65342d00f07f2ec5cc93224089e28084b44a / 0.5.3 | C19: 旧钉版测量，不是最新源代码性能。
A20: 正式请求数 | B20: 10549562 | C20: 36正式阶段合计，不含直连容量预检。
A21: 正式体采样数 | B21: 5276182 | C21: 配置50%，实际统计按各阶段计数给出。
A22: 模板路径 | B22: /Users/xinference/Sync/PT/pk/性能测试指标对照表_xg_vs_newapi_data.xlsx | C22: 只读使用布局与指标定义，没有改写原文件；原历史对照数字不带入。
A23: 模板SHA256 | B23: 4a5dc707d94d6eba4bc18cbd316692d29bfba2071131fcdd1938febf4d1f023d | C23: 用于验证原模板未改。
A24: 原始数据目录 | B24: /Users/xinference/Sync/PT/pk/1013/retest-single-xlite-af50-details | C24: 分片原始指标表逐份记录576个正式摘要的相对路径与SHA256。
A25: 有效阶段总数 | B25: 42 | C25: 36正式+6直连预检均有效、672摘要已独立复算；本表仅含36正式/576摘要。
A26: 原始证据包r10 | B26: 3a5437d2442c4417aa3deb2cf188d50fc7f5b4e2c8c165a7e2601e7e1f29b606 | C26: 包SHA256；保留r10失败预检。
A27: 原始证据包r11 | B27: 3365566e33ab813c65484f1036edf04267b84b709025f3eac8139ad196a80e22 | C27: 包SHA256；r11的DONE记录14阶段/12正式。
A28: 缺失档位/模式 | B28: 集群、500VU、20k及以上：未测 | C28: 不将旧数据当新数据，不外推、不插值。
